Workbook

Sheet LK_Kabkot
A1: PENGUKURAN KINERJA TRIWULANAN TAHUN 2026
A3: Satuan Kerja : | E3: BPS Kota Bima
A4: Nilai SAKIP 2026:
A5: Predikat SAKIP 2026: | E5: =IF(E4>90, "AA/Sangat Memuaskan", IF(E4>80, "A/Memuaskan", IF(E4>70, "BB/Sangat Baik", IF(E4>60, "B/Baik", IF(E4>50, "CC/Cukup (Memadai)", IF(E4>30, "C/Kurang", "D/Sangat Kurang"))))))
A7: Tujuan/Sasaran/Indikator Kinerja | H7: Jenis (IKU atau Proksi) | I7: Jenis (Triwulanan atau Tahunan) | J7: Jenis (% atau Non %) | K7: Target | L7: Satuan | M7: Alokasi Target (Kumulatif) | Q7: Realisasi (Kumulatif) | U7: Capaian Kinerja | AC7: Analisis Pencapaian Kinerja di Triwulan Berjalan | AJ7: Penilaian Kinerja Organisasi (PKO)
U8: Terhadap Target Triwulanan | Y8: Terhadap Target Setahun | AC8: Kendala yang dihadapi pada Ttriwulan Berjalan | AD8: Solusi yang sudah dilakukan pada Triwulan Berjalan | AE8: Rencana Tindak lanjut | AF8: PIC Tindak Lanjut | AG8: Batas Waktu Tindak lanjut | AH8: Link Bukti Dukung Kinerja | AI8: Link Bukti Dukung Tindak Lanjut Triwulan Sebelumnya | AJ8: Normalisasi Capaian PK (1) | AK8: Koreksi Normalisasi Capaian PK Berdasarkan Predikat AKIP (2) | AL8: Nilai Akhir Capaian PK = (1)x(100%-(2))
M9: TW I | N9: TW II | O9: TW III | P9: TW IV | Q9: TW I | R9: TW II | S9: TW III | T9: TW IV | U9: TW I | V9: TW II | W9: TW III | X9: TW IV | Y9: TW I | Z9: TW II | AA9: TW III | AB9: TW IV
A10: T1: Mewujudkan Perumusan Kebijakan dan Pengambilan Keputusan Berbasis Data Statistik Berkualitas dan Insight yang Relevan
B11: 1.1.1 | C11: Terwujudnya Penyediaan Data dan Insight Statistik Kependudukan dan Ketenagakerjaan yang Berkualitas
D12: 1.1.1.1 | E12: Persentase Publikasi/Laporan Statistik Kependudukan dan Ketenagakerjaan yang Berkualitas | H12: IKU | I12: Tahunan | J12: % | K12: =IF(OR(K14=0,ISBLANK(K14)),0,K13/K14*100) | L12: Persen | M12: =IF(OR(M14=0,ISBLANK(M14)),0,M13/M14*100) | N12: =IF(OR(N14=0,ISBLANK(N14)),0,N13/N14*100) | O12: =IF(OR(O14=0,ISBLANK(O14)),0,O13/O14*100) | P12: =IF(OR(P14=0,ISBLANK(P14)),0,P13/P14*100) | Q12: =IF(OR(Q14=0,ISBLANK(Q14)),0,Q13/Q14*100) | R12: =IF(OR(R14=0,ISBLANK(R14)),0,R13/R14*100) | S12: =IF(OR(S14=0,ISBLANK(S14)),0,S13/S14*100) | T12: =IF(OR(T14=0,ISBLANK(T14)),0,T13/T14*100) | U12: =IF(OR(M12=0, ISBLANK(M12)), 0, IF((Q12/M12*100)>120,120,(Q12/M12*100))) | V12: =IF(OR(N12=0, ISBLANK(N12)), 0, IF((R12/N12*100)>120,120,(R12/N12*100))) | W12: =IF(OR(O12=0, ISBLANK(O12)), 0, IF((S12/O12*100)>120,120,(S12/O12*100))) | X12: =IF(OR(P12=0, ISBLANK(P12)), 0, IF((T12/P12*100)>120,120,(T12/P12*100))) | Y12: =IF(OR($K12=0, ISBLANK($K12)), 0, IF((Q12/$K12*100)>120,120,(Q12/$K12*100))) | Z12: =IF(OR($K12=0, ISBLANK($K12)), 0, IF((R12/$K12*100)>120,120,(R12/$K12*100))) | AA12: =IF(OR($K12=0, ISBLANK($K12)), 0, IF((S12/$K12*100)>120,120,(S12/$K12*100))) | AB12: =IF(OR($K12=0, ISBLANK($K12)), 0, IF((T12/$K12*100)>120,120,(T12/$K12*100))) | AJ12: =IF(AB12>=110,"110",AB12) | AK12: =IF(E$5="AA/Sangat Memuaskan","0%",IF(E$5="A/Memuaskan","0%",IF(E$5="BB/Sangat Baik","10%",IF(E$5="B/Baik","15%",IF(E$5="CC/Cukup (Memadai)","20%",IF(E$5="C/Kurang","30%","30%")))))) | AL12: =AJ12*(100%-AK12)
E13: X: Jumlah Publikasi/Laporan Statistik Kependudukan dan Ketenagakerjaan yang berkualitas | K13: 2 | M13: 0 | N13: 0 | O13: 0 | P13: 2
E14: Y: Jumlah seluruh Publikasi/Laporan Statistik Kependudukan dan Ketenagakerjaan yang dihasilkan | K14: 2 | M14: 0 | N14: 0 | O14: 0 | P14: 2
B16: 1.1.3 | C16: Terwujudnya Penyediaan Data dan Insight Statistik Kesejahteraan Rakyat yang Berkualitas
D17: 1.1.3.1 | E17: Persentase Publikasi/Laporan Statistik Kesejahteraan Rakyat yang Berkualitas | H17: IKU | I17: Tahunan | J17: % | K17: =IF(OR(K19=0,ISBLANK(K19)),0,K18/K19*100) | L17: Persen | M17: =IF(OR(M19=0,ISBLANK(M19)),0,M18/M19*100) | N17: =IF(OR(N19=0,ISBLANK(N19)),0,N18/N19*100) | O17: =IF(OR(O19=0,ISBLANK(O19)),0,O18/O19*100) | P17: =IF(OR(P19=0,ISBLANK(P19)),0,P18/P19*100) | Q17: =IF(OR(Q19=0,ISBLANK(Q19)),0,Q18/Q19*100) | R17: =IF(OR(R19=0,ISBLANK(R19)),0,R18/R19*100) | S17: =IF(OR(S19=0,ISBLANK(S19)),0,S18/S19*100) | T17: =IF(OR(T19=0,ISBLANK(T19)),0,T18/T19*100) | U17: =IF(OR(M17=0, ISBLANK(M17)), 0, IF((Q17/M17*100)>120,120,(Q17/M17*100))) | V17: =IF(OR(N17=0, ISBLANK(N17)), 0, IF((R17/N17*100)>120,120,(R17/N17*100))) | W17: =IF(OR(O17=0, ISBLANK(O17)), 0, IF((S17/O17*100)>120,120,(S17/O17*100))) | X17: =IF(OR(P17=0, ISBLANK(P17)), 0, IF((T17/P17*100)>120,120,(T17/P17*100))) | Y17: =IF(OR($K17=0, ISBLANK($K17)), 0, IF((Q17/$K17*100)>120,120,(Q17/$K17*100))) | Z17: =IF(OR($K17=0, ISBLANK($K17)), 0, IF((R17/$K17*100)>120,120,(R17/$K17*100))) | AA17: =IF(OR($K17=0, ISBLANK($K17)), 0, IF((S17/$K17*100)>120,120,(S17/$K17*100))) | AB17: =IF(OR($K17=0, ISBLANK($K17)), 0, IF((T17/$K17*100)>120,120,(T17/$K17*100))) | AJ17: =IF(AB17>=110,"110",AB17) | AK17: =IF(E$5="AA/Sangat Memuaskan","0%",IF(E$5="A/Memuaskan","0%",IF(E$5="BB/Sangat Baik","10%",IF(E$5="B/Baik","15%",IF(E$5="CC/Cukup (Memadai)","20%",IF(E$5="C/Kurang","30%","30%")))))) | AL17: =AJ17*(100%-AK17)
E18: X: Jumlah Publikasi/Laporan Statistik Kesejahteraan Rakyat yang berkualitas | K18: 7 | M18: 0 | N18: 0 | O18: 0 | P18: 7
E19: Y: Jumlah seluruh Publikasi/Laporan Statistik Kesejahteraan Rakyat yang dihasilkan | K19: 7 | M19: 0 | N19: 0 | O19: 0 | P19: 7
B21: 1.1.5 | C21: Terwujudnya penyediaan Data dan Insight Statistik Ketahanan Sosial yang Berkualitas
D22: 1.1.5.1 | E22: Persentase Publikasi/Laporan Statistik Ketahanan Sosial yang Berkualitas | H22: IKU | I22: Tahunan | J22: % | K22: =IF(OR(K24=0,ISBLANK(K24)),0,K23/K24*100) | L22: Persen | M22: =IF(OR(M24=0,ISBLANK(M24)),0,M23/M24*100) | N22: =IF(OR(N24=0,ISBLANK(N24)),0,N23/N24*100) | O22: =IF(OR(O24=0,ISBLANK(O24)),0,O23/O24*100) | P22: =IF(OR(P24=0,ISBLANK(P24)),0,P23/P24*100) | Q22: =IF(OR(Q24=0,ISBLANK(Q24)),0,Q23/Q24*100) | R22: =IF(OR(R24=0,ISBLANK(R24)),0,R23/R24*100) | S22: =IF(OR(S24=0,ISBLANK(S24)),0,S23/S24*100) | T22: =IF(OR(T24=0,ISBLANK(T24)),0,T23/T24*100) | U22: =IF(OR(M22=0, ISBLANK(M22)), 0, IF((Q22/M22*100)>120,120,(Q22/M22*100))) | V22: =IF(OR(N22=0, ISBLANK(N22)), 0, IF((R22/N22*100)>120,120,(R22/N22*100))) | W22: =IF(OR(O22=0, ISBLANK(O22)), 0, IF((S22/O22*100)>120,120,(S22/O22*100))) | X22: =IF(OR(P22=0, ISBLANK(P22)), 0, IF((T22/P22*100)>120,120,(T22/P22*100))) | Y22: =IF(OR($K22=0, ISBLANK($K22)), 0, IF((Q22/$K22*100)>120,120,(Q22/$K22*100))) | Z22: =IF(OR($K22=0, ISBLANK($K22)), 0, IF((R22/$K22*100)>120,120,(R22/$K22*100))) | AA22: =IF(OR($K22=0, ISBLANK($K22)), 0, IF((S22/$K22*100)>120,120,(S22/$K22*100))) | AB22: =IF(OR($K22=0, ISBLANK($K22)), 0, IF((T22/$K22*100)>120,120,(T22/$K22*100))) | AJ22: =IF(AB22>=110,"110",AB22) | AK22: =IF(E$5="AA/Sangat Memuaskan","0%",IF(E$5="A/Memuaskan","0%",IF(E$5="BB/Sangat Baik","10%",IF(E$5="B/Baik","15%",IF(E$5="CC/Cukup (Memadai)","20%",IF(E$5="C/Kurang","30%","30%")))))) | AL22: =AJ22*(100%-AK22)
E23: X: Jumlah Publikasi/Laporan Statistik Ketahanan Sosial yang berkualitas | K23: 5 | M23: 0 | N23: 0 | O23: 0 | P23: 5
E24: Y: Jumlah seluruh Publikasi/Laporan Statistik Ketahanan Sosial yang dihasilkan | K24: 5 | M24: 0 | N24: 0 | O24: 0 | P24: 5
B26: 1.2.1 | C26: Terwujudnya Penyediaan Data dan Insight Statistik Sumber Daya Hayati yang Berkualitas
D27: 1.2.1.1 | E27: Persentase Publikasi/Laporan Statistik Sumber Daya Hayati yang Berkualitas | H27: IKU | I27: Tahunan | J27: % | K27: =IF(OR(K29=0,ISBLANK(K29)),0,K28/K29*100) | L27: Persen | M27: =IF(OR(M29=0,ISBLANK(M29)),0,M28/M29*100) | N27: =IF(OR(N29=0,ISBLANK(N29)),0,N28/N29*100) | O27: =IF(OR(O29=0,ISBLANK(O29)),0,O28/O29*100) | P27: =IF(OR(P29=0,ISBLANK(P29)),0,P28/P29*100) | Q27: =IF(OR(Q29=0,ISBLANK(Q29)),0,Q28/Q29*100) | R27: =IF(OR(R29=0,ISBLANK(R29)),0,R28/R29*100) | S27: =IF(OR(S29=0,ISBLANK(S29)),0,S28/S29*100) | T27: =IF(OR(T29=0,ISBLANK(T29)),0,T28/T29*100) | U27: =IF(OR(M27=0, ISBLANK(M27)), 0, IF((Q27/M27*100)>120,120,(Q27/M27*100))) | V27: =IF(OR(N27=0, ISBLANK(N27)), 0, IF((R27/N27*100)>120,120,(R27/N27*100))) | W27: =IF(OR(O27=0, ISBLANK(O27)), 0, IF((S27/O27*100)>120,120,(S27/O27*100))) | X27: =IF(OR(P27=0, ISBLANK(P27)), 0, IF((T27/P27*100)>120,120,(T27/P27*100))) | Y27: =IF(OR($K27=0, ISBLANK($K27)), 0, IF((Q27/$K27*100)>120,120,(Q27/$K27*100))) | Z27: =IF(OR($K27=0, ISBLANK($K27)), 0, IF((R27/$K27*100)>120,120,(R27/$K27*100))) | AA27: =IF(OR($K27=0, ISBLANK($K27)), 0, IF((S27/$K27*100)>120,120,(S27/$K27*100))) | AB27: =IF(OR($K27=0, ISBLANK($K27)), 0, IF((T27/$K27*100)>120,120,(T27/$K27*100))) | AJ27: =IF(AB27>=110,"110",AB27) | AK27: =IF(E$5="AA/Sangat Memuaskan","0%",IF(E$5="A/Memuaskan","0%",IF(E$5="BB/Sangat Baik","10%",IF(E$5="B/Baik","15%",IF(E$5="CC/Cukup (Memadai)","20%",IF(E$5="C/Kurang","30%","30%")))))) | AL27: =AJ27*(100%-AK27)
E28: X: Jumlah Publikasi/Laporan Statistik Sumber Daya Hayati yang berkualitas | K28: 7 | M28: 0 | N28: 0 | O28: 0 | P28: 7
E29: Y: Jumlah seluruh Publikasi/Laporan Statistik Sumber Daya Hayati yang dihasilkan | K29: 7 | M29: 7 | N29: 7 | O29: 7 | P29: 7
B31: 1.2.2 | C31: Terwujudnya Penyediaan Data dan Insight Statistik Sumber Daya Mineral dan Konstruksi yang Berkualitas
D32: 1.2.2.1 | E32: Persentase publikasi/laporan Statistik Sumber Daya Mineral dan Konstruksi yang Berkualitas | H32: IKU | I32: Tahunan | J32: % | K32: =IF(OR(K34=0,ISBLANK(K34)),0,K33/K34*100) | L32: Persen | M32: =IF(OR(M34=0,ISBLANK(M34)),0,M33/M34*100) | N32: =IF(OR(N34=0,ISBLANK(N34)),0,N33/N34*100) | O32: =IF(OR(O34=0,ISBLANK(O34)),0,O33/O34*100) | P32: =IF(OR(P34=0,ISBLANK(P34)),0,P33/P34*100) | Q32: =IF(OR(Q34=0,ISBLANK(Q34)),0,Q33/Q34*100) | R32: =IF(OR(R34=0,ISBLANK(R34)),0,R33/R34*100) | S32: =IF(OR(S34=0,ISBLANK(S34)),0,S33/S34*100) | T32: =IF(OR(T34=0,ISBLANK(T34)),0,T33/T34*100) | U32: =IF(OR(M32=0, ISBLANK(M32)), 0, IF((Q32/M32*100)>120,120,(Q32/M32*100))) | V32: =IF(OR(N32=0, ISBLANK(N32)), 0, IF((R32/N32*100)>120,120,(R32/N32*100))) | W32: =IF(OR(O32=0, ISBLANK(O32)), 0, IF((S32/O32*100)>120,120,(S32/O32*100))) | X32: =IF(OR(P32=0, ISBLANK(P32)), 0, IF((T32/P32*100)>120,120,(T32/P32*100))) | Y32: =IF(OR($K32=0, ISBLANK($K32)), 0, IF((Q32/$K32*100)>120,120,(Q32/$K32*100))) | Z32: =IF(OR($K32=0, ISBLANK($K32)), 0, IF((R32/$K32*100)>120,120,(R32/$K32*100))) | AA32: =IF(OR($K32=0, ISBLANK($K32)), 0, IF((S32/$K32*100)>120,120,(S32/$K32*100))) | AB32: =IF(OR($K32=0, ISBLANK($K32)), 0, IF((T32/$K32*100)>120,120,(T32/$K32*100))) | AJ32: =IF(AB32>=110,"110",AB32) | AK32: =IF(E$5="AA/Sangat Memuaskan","0%",IF(E$5="A/Memuaskan","0%",IF(E$5="BB/Sangat Baik","10%",IF(E$5="B/Baik","15%",IF(E$5="CC/Cukup (Memadai)","20%",IF(E$5="C/Kurang","30%","30%")))))) | AL32: =AJ32*(100%-AK32)
E33: X: Jumlah Publikasi/Laporan Statistik Sumber Daya Mineral dan Konstruksi yang berkualitas | K33: 3
E34: Y: Jumlah seluruh Publikasi/Laporan Statistik Sumber Daya Mineral dan Konstruksi yang dihasilkan yang dihasilkan | K34: 3
B36: 1.2.3 | C36: Terwujudnya penyediaan Data dan Insight Statistik Industri yang Berkualitas
D37: 1.2.3.1 | E37: Persentase publikasi/laporan Statistik Industri yang Berkualitas | H37: IKU | I37: Tahunan | J37: % | K37: =IF(OR(K39=0,ISBLANK(K39)),0,K38/K39*100) | L37: Persen | M37: =IF(OR(M39=0,ISBLANK(M39)),0,M38/M39*100) | N37: =IF(OR(N39=0,ISBLANK(N39)),0,N38/N39*100) | O37: =IF(OR(O39=0,ISBLANK(O39)),0,O38/O39*100) | P37: =IF(OR(P39=0,ISBLANK(P39)),0,P38/P39*100) | Q37: =IF(OR(Q39=0,ISBLANK(Q39)),0,Q38/Q39*100) | R37: =IF(OR(R39=0,ISBLANK(R39)),0,R38/R39*100) | S37: =IF(OR(S39=0,ISBLANK(S39)),0,S38/S39*100) | T37: =IF(OR(T39=0,ISBLANK(T39)),0,T38/T39*100) | U37: =IF(OR(M37=0, ISBLANK(M37)), 0, IF((Q37/M37*100)>120,120,(Q37/M37*100))) | V37: =IF(OR(N37=0, ISBLANK(N37)), 0, IF((R37/N37*100)>120,120,(R37/N37*100))) | W37: =IF(OR(O37=0, ISBLANK(O37)), 0, IF((S37/O37*100)>120,120,(S37/O37*100))) | X37: =IF(OR(P37=0, ISBLANK(P37)), 0, IF((T37/P37*100)>120,120,(T37/P37*100))) | Y37: =IF(OR($K37=0, ISBLANK($K37)), 0, IF((Q37/$K37*100)>120,120,(Q37/$K37*100))) | Z37: =IF(OR($K37=0, ISBLANK($K37)), 0, IF((R37/$K37*100)>120,120,(R37/$K37*100))) | AA37: =IF(OR($K37=0, ISBLANK($K37)), 0, IF((S37/$K37*100)>120,120,(S37/$K37*100))) | AB37: =IF(OR($K37=0, ISBLANK($K37)), 0, IF((T37/$K37*100)>120,120,(T37/$K37*100))) | AJ37: =IF(AB37>=110,"110",AB37) | AK37: =IF(E$5="AA/Sangat Memuaskan","0%",IF(E$5="A/Memuaskan","0%",IF(E$5="BB/Sangat Baik","10%",IF(E$5="B/Baik","15%",IF(E$5="CC/Cukup (Memadai)","20%",IF(E$5="C/Kurang","30%","30%")))))) | AL37: =AJ37*(100%-AK37)
E38: X: Jumlah Publikasi/Laporan Statistik Industri yang berkualitas | K38: 2
E39: Y: Jumlah seluruh Publikasi/Laporan Statistik Industri yang dihasilkan | K39: 2
B41: 1.3.1 | C41: Terwujudnya Penyediaan Data dan Insight Statistik Distribusi yang Berkualitas
D42: 1.3.1.1 | E42: Persentase Publikasi/Laporan Statistik Distribusi yang Berkualitas | H42: IKU | I42: Tahunan | J42: % | K42: =IF(OR(K44=0,ISBLANK(K44)),0,K43/K44*100) | L42: Persen | M42: =IF(OR(M44=0,ISBLANK(M44)),0,M43/M44*100) | N42: =IF(OR(N44=0,ISBLANK(N44)),0,N43/N44*100) | O42: =IF(OR(O44=0,ISBLANK(O44)),0,O43/O44*100) | P42: =IF(OR(P44=0,ISBLANK(P44)),0,P43/P44*100) | Q42: =IF(OR(Q44=0,ISBLANK(Q44)),0,Q43/Q44*100) | R42: =IF(OR(R44=0,ISBLANK(R44)),0,R43/R44*100) | S42: =IF(OR(S44=0,ISBLANK(S44)),0,S43/S44*100) | T42: =IF(OR(T44=0,ISBLANK(T44)),0,T43/T44*100) | U42: =IF(OR(M42=0, ISBLANK(M42)), 0, IF((Q42/M42*100)>120,120,(Q42/M42*100))) | V42: =IF(OR(N42=0, ISBLANK(N42)), 0, IF((R42/N42*100)>120,120,(R42/N42*100))) | W42: =IF(OR(O42=0, ISBLANK(O42)), 0, IF((S42/O42*100)>120,120,(S42/O42*100))) | X42: =IF(OR(P42=0, ISBLANK(P42)), 0, IF((T42/P42*100)>120,120,(T42/P42*100))) | Y42: =IF(OR($K42=0, ISBLANK($K42)), 0, IF((Q42/$K42*100)>120,120,(Q42/$K42*100))) | Z42: =IF(OR($K42=0, ISBLANK($K42)), 0, IF((R42/$K42*100)>120,120,(R42/$K42*100))) | AA42: =IF(OR($K42=0, ISBLANK($K42)), 0, IF((S42/$K42*100)>120,120,(S42/$K42*100))) | AB42: =IF(OR($K42=0, ISBLANK($K42)), 0, IF((T42/$K42*100)>120,120,(T42/$K42*100))) | AJ42: =IF(AB42>=110,"110",AB42) | AK42: =IF(E$5="AA/Sangat Memuaskan","0%",IF(E$5="A/Memuaskan","0%",IF(E$5="BB/Sangat Baik","10%",IF(E$5="B/Baik","15%",IF(E$5="CC/Cukup (Memadai)","20%",IF(E$5="C/Kurang","30%","30%")))))) | AL42: =AJ42*(100%-AK42)
E43: X: Jumlah Publikasi/Laporan Statistik Distribusi yang berkualitas | K43: 9 | M43: 0 | N43: 0 | O43: 0 | P43: 9
E44: Y: Jumlah seluruh Publikasi/Laporan Statistik Distribusi yang dihasilkan | K44: 9 | M44: 0 | N44: 0 | O44: 0 | P44: 9
B46: 1.3.3 | C46: Terwujudnya Penyediaan Data dan Insight Statistik Harga yang Berkualitas
D47: 1.3.3.1 | E47: Persentase Publikasi/laporan Statistik Harga yang Berkualitas | H47: IKU | I47: Tahunan | J47: % | K47: =IF(OR(K49=0,ISBLANK(K49)),0,K48/K49*100) | L47: Persen | M47: =IF(OR(M49=0,ISBLANK(M49)),0,M48/M49*100) | N47: =IF(OR(N49=0,ISBLANK(N49)),0,N48/N49*100) | O47: =IF(OR(O49=0,ISBLANK(O49)),0,O48/O49*100) | P47: =IF(OR(P49=0,ISBLANK(P49)),0,P48/P49*100) | Q47: =IF(OR(Q49=0,ISBLANK(Q49)),0,Q48/Q49*100) | R47: =IF(OR(R49=0,ISBLANK(R49)),0,R48/R49*100) | S47: =IF(OR(S49=0,ISBLANK(S49)),0,S48/S49*100) | T47: =IF(OR(T49=0,ISBLANK(T49)),0,T48/T49*100) | U47: =IF(OR(M47=0, ISBLANK(M47)), 0, IF((Q47/M47*100)>120,120,(Q47/M47*100))) | V47: =IF(OR(N47=0, ISBLANK(N47)), 0, IF((R47/N47*100)>120,120,(R47/N47*100))) | W47: =IF(OR(O47=0, ISBLANK(O47)), 0, IF((S47/O47*100)>120,120,(S47/O47*100))) | X47: =IF(OR(P47=0, ISBLANK(P47)), 0, IF((T47/P47*100)>120,120,(T47/P47*100))) | Y47: =IF(OR($K47=0, ISBLANK($K47)), 0, IF((Q47/$K47*100)>120,120,(Q47/$K47*100))) | Z47: =IF(OR($K47=0, ISBLANK($K47)), 0, IF((R47/$K47*100)>120,120,(R47/$K47*100))) | AA47: =IF(OR($K47=0, ISBLANK($K47)), 0, IF((S47/$K47*100)>120,120,(S47/$K47*100))) | AB47: =IF(OR($K47=0, ISBLANK($K47)), 0, IF((T47/$K47*100)>120,120,(T47/$K47*100))) | AJ47: =IF(AB47>=110,"110",AB47) | AK47: =IF(E$5="AA/Sangat Memuaskan","0%",IF(E$5="A/Memuaskan","0%",IF(E$5="BB/Sangat Baik","10%",IF(E$5="B/Baik","15%",IF(E$5="CC/Cukup (Memadai)","20%",IF(E$5="C/Kurang","30%","30%")))))) | AL47: =AJ47*(100%-AK47)
E48: X: Jumlah Publikasi/Laporan Statistik Harga yang berkualitas | K48: 4 | M48: 0 | N48: 0 | O48: 0 | P48: 4
E49: Y: Jumlah seluruh Publikasi/Laporan Statistik Harga yang dihasilkan | K49: 4 | M49: 0 | N49: 0 | O49: 0 | P49: 4
...

Sheet 1.1.1.1
A1: Rincian Output | B1: Realisasi Volume RO | C1: Progres Pelaksanaan Kegiatan (Persen) | D1: Realisasi yang telah dilaksanakan (Berikan Narasi)
A2: 1 | B2: 2 | C2: 3 | D2: 4
A3: 2905 BMA 004. Publikasi/Laporan Survei Angkatan Kerja Nasional | B3: 0 | C3: 0.2522 | D3: Pelaksanaan Sakernas Februari 2026 telah selesai dilaksanakan sebesar 100 persen dengan progres kegiatan terhadap total pelaksanaan Sakernas sebesar 25,22 persen
A4: 2905 BMA 005. Publikasi/Laporan Statistik Kependudukan dan Ketenagakerjaan | B4: 0 | C4: 0 | D4: Tidak ada pelaksanaan kegiatan Statistik Kependudukan dan Ketenagakerjaan di tahun 2026

Sheet 1.1.3.1.
A1: Rincian Output | B1: Realisasi Volume RO | C1: Progres Pelaksanaan Kegiatan (Persen) | D1: Realisasi yang telah dilaksanakan (Berikan Narasi)
A2: 2906 BMA 003. Publikasi/Laporan Statistik Kesejahteraan Rakyat | B2: 0 | C2: 0 | D2: Tidak ada pelaksanaan kegiatan Publikasi/Laporan Statistik Kesejahteraan Rakyat di tahun 2026
A3: 2906 BMA 005. Publikasi/Laporan Data Tunggal Sosial dan Ekonomi Nasional | B3: 0 | C3: 0.1712 | D3: Pelaksanaan kegiatan Koordinasi, Kolaborasi dan pelaksanaan kegiatan Groundchek PBI Tahap I, Pelatihan Petugas Groundcek PLN serta pelatihan kegiatan GC PBI Tahap II
A4: 2906 BMA 006. Publikasi/Laporan Survei Sosial Ekonomi Nasional | B4: 0 | C4: 0.5743 | D4: Pelaksanaan Susenas dan Seruti TW 1 Tahun 2026 telah diselesaikan.

Sheet 1.1.5.1
A1: Rincian Output | B1: Realisasi Volume RO | C1: Progres Pelaksanaan Kegiatan (Persen) | D1: Realisasi yang telah dilaksanakan (Berikan Narasi)
A2: 2907 BMA 006. Publikasi/Laporan Statistik Ketahanan Sosial | B2: 0 | C2: 16,24% | D2: Pada triwulan I 2026, kegiatan Statistik Ketahanan Politik dan Keamanan (Statpolkam) yang telah dilaksanakan antara lain, persiapan kegiatan survei STATPOLKAM 2026 dengan melakukan pengumpulan data yang terintegrasi dengan pengumpulan data Kota Bima Dalam Angka 2026
A3: 2907 BMA 008. Publikasi/Laporan Pendataan Potensi Desa | B3: 0 | C3: 24,56% | D3: Pada triwulan I 2026, kegiatan Pendataan Pemutakhiran Data Perkembangan Desa (Potensi Desa) yang telah dilaksanakan yaitu persiapan berupa pelatihan Inda dan Penentuan Petugas Podes 2026

Sheet 1.2.1.1.
A1: Rincian Output | B1: Realisasi Volume RO | C1: Progres Pelaksanaan Kegiatan (Persen) | D1: Realisasi yang telah dilaksanakan (Berikan Narasi)
A2: 2910 BMA 007. Publikasi/Laporan Statistik Tanaman Pangan | B2: 0 | C2: 0.1353 | D2: Kegiatan yang telah dilaksanakan antara lain pengamatan KSA Padi dan Jagung sudah 100 persen dilakukan pengamatan pada triwulan I tahun 2026. Ubinan Padi dan Palawija masih berjalan dan baru terealisasi sekitar 75 persen karena rentang waktu pendataan adalah subround 1 (Januari-April), petugas lapangan masih menjalankan pendataan untuk memenuhi target. Untuk kegiatan laporan SP palwaija yang berasal dari Dinas Pertanian telah terealisasi 100 persen.
A3: 2910 BMA 008. Publikasi/Laporan Statistik Hortikultura dan Perkebunan | B3: 0 | C3: 0.3333 | D3: Untuk kegiatan pada Satatistik Hortikultura dan Perkebunan, kegiatan yang telah selesai pelaksanaannya 100 persen adalah kegiatan listing Survei Indeks Produksi Hortikultura (VIP-Horti) Tahun 2026, sedangkan untuk kegiatan pendataan akan dilaksanakan secara triwulanan pada bulan April, Juli, dan Oktober 2026.
A4: 2909 BMA 005. Publikasi/Laporan Statistik Peternakan, Perikanan, dan Kehutanan | B4: 0 | C4: 0.1865 | D4: Kegiatan di Statistik Peternakan, Perikanan, dan Kehutanan yang dilakukan pada Triwulan I Tahun 2026 adalah Laporan Pemotongan Ternak Bulanan (LPTB) yang dilakukan setiap bulannya dan telah 100 persen realisasi sesuai jadwal. Selain itu telah dilakukan koordinasi bersama Dinas Perikanan untuk pengumpulan Laporan Pendaratan Ikan Tradisional (PIT) Triwulan 4 Tahun 2025, kegiatan ini telah dilaksnakan sesuai jadwal dan 100 persen terealisasi.

Sheet 1.2.2.1.
A1: Rincian Output | B1: Realisasi Volume RO | C1: Progres Pelaksanaan Kegiatan (Persen) | D1: Realisasi yang telah dilaksanakan (Berikan Narasi)
A2: 2904 BMA 006. Publikasi/Laporan Statistik Sumber Daya Mineral dan Konstruksi | B2: 0 | C2: 0.2056 | D2: Kegiatan yang telah dilaksanakan pada Triwulan I Tahun 2026 antara lain Survei Konstruksi Triwulanan (SKTR) Triwulan 4 Tahun 2025, Survei Air Bersih Triwulan 4 Tahun 2025, dan Updating Direktori Perusahaan Pertambangan dan Energi (UDPE) Tahun 2026. Semua kegiatan tersebut telah dilaksanakan sesuai jadwal dan sudah terealisasi 100 persen.

Sheet 1.2.3.1.
A1: Rincian Output | B1: Realisasi Volume RO | C1: Progres Pelaksanaan Kegiatan (Persen) | D1: Realisasi yang telah dilaksanakan (Berikan Narasi)
A2: 2904 BMA 006. Publikasi/Laporan Statistik Industri yang berkualitas | B2: 0 | C2: 0.3571 | D2: Kegiatan Statistik Industri yang telah realisasi 100 persen adalah pendataan Survei Industri Besar Sedang (IBS) Triwulan 4 Tahun 2025 dan Survei Industri Mikro Kecil (IMK) Triwulan 4 Tahun 2025 yang dilaksanakan pada bulan Januari 2026, serta Listing IMK Triwulanan Tahun 2026 yang dilaksanakan pada bulan Maret 2026.

Sheet 1.3.1.1.
A1: Rincian Output | B1: Realisasi Volume RO | C1: Progres Pelaksanaan Kegiatan (Persen) | D1: Realisasi yang telah dilaksanakan (Berikan Narasi)
A2: 2902 BMA 004. Publikasi/Laporan Statistik Distribusi | B2: 0 | C2: 0.175 | D2: Pelaksanaan kegitan statistik distribusi yang telah terealisasi 100 persen di TW I adalah pendatan Lapangan dokumen angkutan darat PJ II/5 yang dilaksanakan pada bulan Februari 2026. sementara untuk pendataan SIMOPPEL (bersifat bulanan ) untuk bulan (Jauari-Maret) 2026 sudah terealisasi 100 persen
A3: 2902 BMA 006. Publikasi/Laporan Sensus Ekonomi | B3: 0 | C3: 0.2086 | D3: Kegiatan publisitas SE yg sudah terlaksana dan masih berjalan yaitu pelaksanaan berbagai sosialisasi Sensus Ekonomi meliputi pembuatan standing banner, roll banner, leaflet, dan spanduk.
A4: 2900 BMA 005. Dokumen/Laporan Pengembangan Metodologi Kegiatan Statistik | B4: 0 | C4: 0.175 | D4: Pelaksanaan GC SBR melalui matchapro dan surat pernyataan pelaksanan GC SBR telah selesai 100 persen.
L48: 0 | M48: 0 | N48: 0
L49: 0 | M49: 0 | N49: 0

Sheet 1.3.3.1.
A1: Rincian Output | B1: Realisasi Volume RO | C1: Progres Pelaksanaan Kegiatan (Persen) | D1: Realisasi yang telah dilaksanakan (Berikan Narasi)
A2: 2903 BMA 009. Publikasi/Laporan Statistik Harga | B2: 0 | C2: 0.2233 | D2: Kegiatan Statistik Harga yang sudah terselesaikan 100 persen adalah survey harga produsen identifikasi komoditas utama pada bulan Januari 2026 (Tahunan), Untuk Krgiatan lain seperti SHP, SHPB masih berjalan (pencacahan rutin bulanan)
A3: 2903 QMA 006. Publikasi/Laporan Penyusunan Inflasi | B3: 0 | C3: 0.1376 | D3: Kegiatan penyusunan inflasi masih berjalan karena merupakan pendataan rutin bulanan (HK 1,2,3,4,5 dan 6)
A4: 2903 BMA 007. Publikasi/Laporan Survei Biaya Hidup | B4: 0 | C4: 0 | D4: Belum ada kegiatan

Sheet 1.3.5.1.
A1: Rincian Output | B1: Realisasi Volume RO | C1: Progres Pelaksanaan Kegiatan (Persen) | D1: Realisasi yang telah dilaksanakan (Berikan Narasi)
A2: 2908 BMA 004. Publikasi/Laporan Statistik Keuangan, Teknologi Informasi, dan Pariwisata | B2: 0 | C2: 0.1933 | D2: Kegiatan Statistik Pariwisata yang sudah terealisasi 100 persen adalah pelatihan petugas survey Bidang Jasa Pariwisata pada bulan Maret 2026. Untuk kegiatan lain seperti VHTS masih berjalan karena merupakan kegiatan Rutin Bulanan

Sheet 1.4.1.1.
A1: Rincian Output | B1: Realisasi Volume RO | C1: Progres Pelaksanaan Kegiatan (Persen) | D1: Realisasi yang telah dilaksanakan (Berikan Narasi)
A2: 2899 BMA 006. Publikasi/Laporan Neraca Produksi | B2: 0 | C2: 0.1833 | D2: Pada triwulan I 2026, kegiatan yang telah dilaksanakan diantaranya SKTNP Tahap I, rekonsiliasi PDRB Lapangan Usaha Triwulan IV 2025 dan Tahun 2025, penyusunan publikasi PDRB Lapangan Usaha 2025, serta persiapan SKTNP Tahap II.

Sheet 1.4.1.2
A1: Rincian Output | B1: Realisasi Volume RO | C1: Progres Pelaksanaan Kegiatan (Persen) | D1: Realisasi yang telah dilaksanakan (Berikan Narasi)
A2: 2898 BMA 007. Publikasi/Laporan Statistik Neraca Pengeluaran | B2: 0 | C2: 0.16 | D2: Pada triwulan I 2026, kegiatan Statistik Neraca Pengeluaran yang telah dilaksanakan antara lain, persiapan hingga diseminasi angka PDRB Pengeluaran Triwulan IV Tahun 2025 dan persiapan kegiatan SKLNPT TW I 2026 (pemilihan dan pelatihan petugas serta alokasi beban tugas)

Sheet 1.4.1.3
A1: Rincian Output | B1: Realisasi Volume RO | C1: Progres Pelaksanaan Kegiatan (Persen) | D1: Realisasi yang telah dilaksanakan (Berikan Narasi)
A2: 2896 BMA U01. Publikasi/Laporan Indeks Pembangunan Manusia | B2: 0 | C2: 0 | D2: Belum dilaksanakan
A3: 2896 BMA 004. Publikasi/Laporan Analisis dan Pengembangan Statistik | B3: 0 | C3: 0 | D3: Kegiatan masih belum dimulai (masih dalam tahap perencanaan).
A4: 2896 QMA 006. Pemanfaatan Big Data untuk Statistik Resmi | B4: 0 | C4: 0 | D4: Belum dilaksanakan

Sheet 2.1.4.1.
A1: Rincian Output | B1: Realisasi Volume RO | C1: Progres Pelaksanaan Kegiatan (Persen) | D1: Realisasi yang telah dilaksanakan (Berikan Narasi)
A2: 2907 UBB 006. Pembinaan Desa Cinta Statistik | B2: 5 | C2: 26,49% | D2: Telah dilakukan proses persiapan pembinaan kelurahan cinta statistik berupa koordinasi kepada organisasi perangkat daerah (OPD) sebagai bentuk dukungan kegiatan serta pertimbangan dalam pemilihan lokus pembinaan. Selain itu, koordinasi juga dilakukan pada level kecamatan dan kelurahan pembinaan sebagai bentuk pemberitahuan awal kepada kelurahan terkait program kelirahan cinta statistik.

Sheet 2.5.1.1.
A1: Rincian Output | B1: Realisasi Volume RO | C1: Progres Pelaksanaan Kegiatan (Persen) | D1: Realisasi yang telah dilaksanakan (Berikan Narasi)
A2: 2897 QDB 003. Pembinaan Statistik Sektoral | B2: 0 | C2: 0.25 | D2: Pembinaan Statistik Sektoral yang telah dilaksanakan pada triwulan I yaitu identifikasi kegiatan statistik prioritas pembinaan dan pembinaan mengenai peningkatan kualitas data statistik sektoral

Sheet 2.7.1.1.
A1: Rincian Output | B1: Realisasi Volume RO | C1: Progres Pelaksanaan Kegiatan (Persen) | D1: Realisasi yang telah dilaksanakan (Berikan Narasi)
A2: 2897 BMA 004. Laporan Diseminasi dan Metadata Statistik | B2: 0 | C2: 0.65 | D2: Pada kegiatan focus groud discussion Kota Bima Dalam Angka telah dilaksanakan sosialisasi terkait rekomendasi statisik, metadata statistik Variabel dan Metadata statistik Indikator pada sesi pleno kualitas data statistik
A3: 2901 CAN 004. Pengembangan Infrastruktur dan Layanan Teknologi Informasi dan Komunikasi | B3: 0 | C3: 0.27 | D3: Telah dilakukan pembelian lisensi software: - Capcut (Bulan Januari) - Google One (Bulan Februari) - Onedrive (Bulan Maret)

Sheet Anggaran
A1: Sasaran Kegiatan | B1: PAGU Awal (Rp) | C1: PAGU Revisi Sampai dengan triwulan berjalan (terisi jika satker melakukan revisi PAGU), jika tidak ada revisi PAGU maka diisi “-“ (Rp) | D1: Realisasi sampai dengan triwulan Berjalan (Rp)
A2: Terwujudnya Penyediaan Data Dan Insight Statistik Kependudukan Dan Ketenagakerjaan Yang Berkualitas | B2: 98908000 | C2: 96658000 | D2: 23787660
A3: Terwujudnya Penyediaan Data Dan Insight Statistik Kesejahteraan Rakyat Yang Berkualitas | B3: 346573000 | C3: 349293000 | D3: 197965000
A4: Terwujudnya Penyediaan Data Dan Insight Statistik Ketahanan Sosial Yang Berkualitas | B4: 12006000 | C4: 11881000 | D4: 0
A5: Terwujudnya Penyediaan Data Dan Insight Statistik Sumber Daya Hayati Yang Berkualitas | B5: 121113000 | C5: 120583000 | D5: 15420000
A6: Terwujudnya Penyediaan Data Dan Insight Statistik Sumber Daya Mineral dan Konstruksi Yang Berkualitas | B6: 17625000 | C6: 15929000 | D6: 3625500
A7: Terwujudnya Penyediaan Data Dan Insight Statistik Industri Yang Berkualitas | B7: 35921000 | C7: 36502000 | D7: 4239000
A8: Terwujudnya Penyediaan Data Dan Insight Statistik Distribusi Yang Berkualitas | B8: 1849706000 | C8: 792883000 | D8: 10479600
A9: Terwujudnya Penyediaan Data Dan Insight Statistik Harga Yang Berkualitas | B9: 458491000 | C9: 453975000 | D9: 53428000
A10: Terwujudnya Penyediaan Data Dan Insight Statistik Jasa Yang Berkualitas | B10: 45059000 | C10: 43598000 | D10: 7887500
A11: Terwujudnya Penyediaan Data Dan Insight Statistik Lintas Sektor Yang Berkualitas | B11: 38368000 | C11: 37093000 | D11: 4694000
A12: Terwujudnya Kapasitas Tata Kelola Pemerintah Desa Untuk Menghasilkan Statistik Berkualitas | B12: 15995000 | C12: 11484000 | D12: 0
A13: Terwujudnya Penguatan Penyelenggaraan Pembinaan Statistik Sektoral Kementerian/Lembaga/Pemerintah Daerah | B13: 3530000 | C13: 2530000 | D13: 0
... A15: Terwujudnya Dukungan Manajemen Pada Bps Provinsi Dan Bps Kabupaten/Kota | B15: 4463215000 | C15: 4429149000 | D15: 1225841192
A16: Total | B16: =SUM(B2:B15) | C16: =SUM(C2:C15) | D16: =SUM(D2:D15)

Sheet FRA_input
A2: Indikator Kinerja/Uraian | E2: Jenis | F2: Target | G2: Satuan | H2: Alokasi Target | L2: Realisasi | P2: Capaian Kinerja | X2: Analisis Pencapaian Kinerja di Triwulan Berjalan
P3: Terhadap Target Triwulanan | T3: Terhadap Target Setahun | X3: Kendala | Y3: Solusi | Z3: RTL | AA3: PIC TL | AB3: Batas Waktu TL | AC3: Link Bukti Dukung
H4: TW1 | I4: TW2 | J4: TW3 | K4: TW4 | L4: TW1 | M4: TW2 | N4: TW3 | O4: TW4 | P4: TW1 | Q4: TW2 | R4: TW3 | S4: TW4 | T4: TW1 | U4: TW2 | V4: TW3 | W4: TW4
A5: ESELON I
A6: T1
B7: S1
C8: IKU 1
D9: Proksi 1.1
D10: Proksi 1.2
D11: Proksi 1.3
C12: IKU 2
D13: Proksi 2.1
D14: Proksi 2.2
D15: Proksi 2.3
A16: T2
B17: S2
C18: IKU 3
D19: Proksi 3.1
D20: Proksi 3.2
D21: Proksi 4.3
C22: IKU 4
D23: Proksi 5.1
D24: Proksi 5.2
D25: Proksi 2.3
O27: Capaian Proksi IKU 1 | P27: rata2 capaian proksi IKU 1
O28: Capaian Proksi IKU 2 | P28: rata2 capaian proksi IKU 2
O29: Capaian Proksi IKU 3 | P29: rata2 capaian proksi IKU 3
O30: Capaian Proksi IKU 4 | P30: rata2 capaian proksi IKU 4
O31: Capaian IKU 1
O32: Capaian IKU 2
O33: Capaian IKU 3
O34: Capaian IKU 4
O35: Capaian Sasaran 1 | P35: rata2 capaian IKU 12
O36: Capaian Sasaran 2 | P36: rata2 capaian IKU 34
O37: Capaian Tujuan 1
O38: Capaian Tujuan 2
A40: ESELON II
A41: T1
B42: S1
C43: IKU 1
...

Sheet FRA_view
A2: Indikator Kinerja/Uraian | E2: Jenis | F2: Target | G2: Satuan | H2: Alokasi Target | L2: Realisasi | P2: Capaian Kinerja | X2: Analisis Pencapaian Kinerja di Triwulan Berjalan
P3: Terhadap Target Triwulanan | T3: Terhadap Target Setahun | X3: Kendala | Y3: Solusi | Z3: RTL | AA3: PIC TL | AB3: Batas Waktu TL | AC3: Link Bukti Dukung
H4: TW1 | I4: TW2 | J4: TW3 | K4: TW4 | L4: TW1 | M4: TW2 | N4: TW3 | O4: TW4 | P4: TW1 | Q4: TW2 | R4: TW3 | S4: TW4 | T4: TW1 | U4: TW2 | V4: TW3 | W4: TW4
A5: ESELON I
A6: T1
B7: S1
C8: IKU 1 | E8: =FRA_input!E8 | F8: =FRA_input!F8 | G8: =FRA_input!G8 | H8: =FRA_input!H8 | I8: =FRA_input!I8 | J8: =FRA_input!J8 | K8: =FRA_input!K8 | L8: =FRA_input!L8 | ... AC8: =FRA_input!AC8
D9: Proksi 1.1 | E9: =FRA_input!E9 | F9: =FRA_input!F9 | G9: =FRA_input!G9 | H9: =FRA_input!H9 | I9: =FRA_input!I9 | J9: =FRA_input!J9 | K9: =FRA_input!K9 | L9: =FRA_input!L9 | ... AC9: =FRA_input!AC9
D10: Proksi 1.2 | E10: =FRA_input!E10 | F10: =FRA_input!F10 | G10: =FRA_input!G10 | H10: =FRA_input!H10 | I10: =FRA_input!I10 | J10: =FRA_input!J10 | K10: =FRA_input!K10 | L10: =FRA_input!L10 | ... AC10: =FRA_input!AC10
D11: Proksi 1.3 | E11: =FRA_input!E11 | F11: =FRA_input!F11 | G11: =FRA_input!G11 | H11: =FRA_input!H11 | I11: =FRA_input!I11 | J11: =FRA_input!J11 | K11: =FRA_input!K11 | L11: =FRA_input!L11 | ... AC11: =FRA_input!AC11
C12: IKU 2 | E12: =FRA_input!E12 | F12: =FRA_input!F12 | G12: =FRA_input!G12 | H12: =FRA_input!H12 | I12: =FRA_input!I12 | J12: =FRA_input!J12 | K12: =FRA_input!K12 | L12: =FRA_input!L12 | ... AC12: =FRA_input!AC12
D13: Proksi 2.1 | E13: =FRA_input!E13 | F13: =FRA_input!F13 | G13: =FRA_input!G13 | H13: =FRA_input!H13 | I13: =FRA_input!I13 | J13: =FRA_input!J13 | K13: =FRA_input!K13 | L13: =FRA_input!L13 | ... AC13: =FRA_input!AC13
D14: Proksi 2.2 | E14: =FRA_input!E14 | F14: =FRA_input!F14 | G14: =FRA_input!G14 | H14: =FRA_input!H14 | I14: =FRA_input!I14 | J14: =FRA_input!J14 | K14: =FRA_input!K14 | L14: =FRA_input!L14 | ... AC14: =FRA_input!AC14
D15: Proksi 2.3 | E15: =FRA_input!E15 | F15: =FRA_input!F15 | G15: =FRA_input!G15 | H15: =FRA_input!H15 | I15: =FRA_input!I15 | J15: =FRA_input!J15 | K15: =FRA_input!K15 | L15: =FRA_input!L15 | ... AC15: =FRA_input!AC15
A16: T2 | E16: =FRA_input!E16 | F16: =FRA_input!F16 | G16: =FRA_input!G16 | H16: =FRA_input!H16 | I16: =FRA_input!I16 | J16: =FRA_input!J16
B17: S2 | E17: =FRA_input!E17 | F17: =FRA_input!F17 | G17: =FRA_input!G17 | H17: =FRA_input!H17 | I17: =FRA_input!I17 | J17: =FRA_input!J17
C18: IKU 3 | E18: =FRA_input!E18 | F18: =FRA_input!F18 | G18: =FRA_input!G18 | H18: =FRA_input!H18 | I18: =FRA_input!I18 | J18: =FRA_input!J18 | K18: =FRA_input!K18 | L18: =FRA_input!L18 | ... AC18: =FRA_input!AC18
D19: Proksi 3.1 | E19: =FRA_input!E19 | F19: =FRA_input!F19 | G19: =FRA_input!G19 | H19: =FRA_input!H19 | I19: =FRA_input!I19 | J19: =FRA_input!J19 | K19: =FRA_input!K19 | L19: =FRA_input!L19 | ... AC19: =FRA_input!AC19
D20: Proksi 3.2 | E20: =FRA_input!E20 | F20: =FRA_input!F20 | G20: =FRA_input!G20 | H20: =FRA_input!H20 | I20: =FRA_input!I20 | J20: =FRA_input!J20 | K20: =FRA_input!K20 | L20: =FRA_input!L20 | ... AC20: =FRA_input!AC20
D21: Proksi 4.3 | E21: =FRA_input!E21 | F21: =FRA_input!F21 | G21: =FRA_input!G21 | H21: =FRA_input!H21 | I21: =FRA_input!I21 | J21: =FRA_input!J21 | K21: =FRA_input!K21 | L21: =FRA_input!L21 | ... AC21: =FRA_input!AC21
C22: IKU 4 | E22: =FRA_input!E22 | F22: =FRA_input!F22 | G22: =FRA_input!G22 | H22: =FRA_input!H22 | I22: =FRA_input!I22 | J22: =FRA_input!J22 | K22: =FRA_input!K22 | L22: =FRA_input!L22 | ... AC22: =FRA_input!AC22
D23: Proksi 5.1 | E23: =FRA_input!E23 | F23: =FRA_input!F23 | G23: =FRA_input!G23 | H23: =FRA_input!H23 | I23: =FRA_input!I23 | J23: =FRA_input!J23 | K23: =FRA_input!K23 | L23: =FRA_input!L23 | ... AC23: =FRA_input!AC23
D24: Proksi 5.2 | E24: =FRA_input!E24 | F24: =FRA_input!F24 | G24: =FRA_input!G24 | H24: =FRA_input!H24 | I24: =FRA_input!I24 | J24: =FRA_input!J24 | K24: =FRA_input!K24 | L24: =FRA_input!L24 | ... AC24: =FRA_input!AC24
D25: Proksi 2.3 | E25: =FRA_input!E25 | F25: =FRA_input!F25 | G25: =FRA_input!G25 | H25: =FRA_input!H25 | I25: =FRA_input!I25 | J25: =FRA_input!J25 | K25: =FRA_input!K25 | L25: =FRA_input!L25 | ... AC25: =FRA_input!AC25
D27: REPORT CAPAIAN KINERJA | O27: Capaian Proksi IKU 1 | P27: rata2 capaian proksi IKU 1
O28: Capaian Proksi IKU 2 | P28: rata2 capaian proksi IKU 2
O29: Capaian Proksi IKU 3 | P29: rata2 capaian proksi IKU 3
O30: Capaian Proksi IKU 4 | P30: rata2 capaian proksi IKU 4
O31: Capaian IKU 1
O32: Capaian IKU 2
O33: Capaian IKU 3
O34: Capaian IKU 4
O35: Capaian Sasaran 1 | P35: rata2 capaian IKU 12
O36: Capaian Sasaran 2 | P36: rata2 capaian IKU 34
O37: Capaian Tujuan 1
O38: Capaian Tujuan 2
A40: ESELON II
A41: T1
B42: S1
C43: IKU 1 | E43: =FRA_input!E43 | F43: =FRA_input!F43 | G43: =FRA_input!G43 | H43: =FRA_input!H43 | I43: =FRA_input!I43 | J43: =FRA_input!J43 | K43: =FRA_input!K43 | L43: =FRA_input!L43 | ... AC43: =FRA_input!AC43
...
